<mujoco model="left_shadow_hand scene">
  <compiler angle="radian" meshdir="assets/"/>

  <option impratio="10" cone="elliptic"/>

  <visual>
    <global azimuth="220" elevation="-30"/>
    <quality shadowsize="8192"/>
    <rgba haze="0.15 0.25 0.35 1"/>
  </visual>

  <statistic extent="0.3" center="0.3 0 0"/>

  <default>
    <default class="left_hand">
      <mesh scale="0.001 0.001 0.001"/>
      <joint armature="0.0002" damping="0.05" frictionloss="0.01"/>
      <general forcerange="-1 1" biastype="affine" biasprm="0 -1"/>
      <default class="wrist">
        <joint damping="0.5"/>
        <default class="wrist_y">
          <joint range="-0.523599 0.174533"/>
          <general ctrlrange="-0.523599 0.174533" forcerange="-10 10" gainprm="10" biasprm="0 -10"/>
        </default>
        <default class="wrist_x">
          <joint range="-0.698132 0.488692"/>
          <general ctrlrange="-0.698132 0.488692" forcerange="-5 5" gainprm="8" biasprm="0 -8"/>
        </default>
      </default>
      <default class="thumb">
        <default class="thbase">
          <joint range="-1.0472 1.0472"/>
          <general ctrlrange="-1.0472 1.0472" forcerange="-3 3" gainprm="0.4" biasprm="0 -0.4"/>
        </default>
        <default class="thproximal">
          <joint range="0 1.22173"/>
          <general ctrlrange="0 1.22173" forcerange="-2 2"/>
        </default>
        <default class="thhub">
          <joint range="-0.20944 0.20944"/>
          <general ctrlrange="-0.20944 0.20944" gainprm="0.5" biasprm="0 -0.5"/>
        </default>
        <default class="thmiddle">
          <joint range="-0.698132 0.698132"/>
          <general ctrlrange="-0.698132 0.698132" gainprm="1.5" biasprm="0 -1.5"/>
        </default>
        <default class="thdistal">
          <joint range="-0.261799 1.5708"/>
          <general ctrlrange="-0.261799 1.5708"/>
        </default>
      </default>
      <default class="metacarpal">
        <joint range="0 0.785398"/>
        <general ctrlrange="0 0.785398"/>
      </default>
      <default class="knuckle">
        <joint range="-0.349066 0.349066"/>
        <general ctrlrange="-0.349066 0.349066"/>
      </default>
      <default class="proximal">
        <joint range="-0.261799 1.5708"/>
        <general ctrlrange="-0.261799 1.5708"/>
      </default>
      <default class="middle_distal">
        <joint range="0 1.5708"/>
        <general ctrlrange="0 3.1415" gainprm="0.5" biasprm="0 -0.5"/>
      </default>
      <default class="plastic">
        <geom solref="0.005" solimp="0.5 0.99 0.0001"/>
        <default class="plastic_visual">
          <geom type="mesh" contype="0" conaffinity="0" group="2" material="black"/>
        </default>
        <default class="plastic_collision">
          <geom group="3"/>
        </default>
      </default>
    </default>
    <default class="right/main">
      <default class="right/right_hand">
        <mesh scale="0.001 0.001 0.001"/>
        <joint armature="0.0002" damping="0.05" frictionloss="0.01"/>
        <general forcerange="-1 1" biastype="affine" biasprm="0 -1"/>
        <default class="right/wrist">
          <joint damping="0.5"/>
          <default class="right/wrist_y">
            <joint range="-0.523599 0.174533"/>
            <general ctrlrange="-0.523599 0.174533" forcerange="-10 10" gainprm="10" biasprm="0 -10"/>
          </default>
          <default class="right/wrist_x">
            <joint range="-0.698132 0.488692"/>
            <general ctrlrange="-0.698132 0.488692" forcerange="-5 5" gainprm="8" biasprm="0 -8"/>
          </default>
        </default>
        <default class="right/thumb">
          <default class="right/thbase">
            <joint range="-1.0472 1.0472"/>
            <general ctrlrange="-1.0472 1.0472" forcerange="-3 3" gainprm="0.4" biasprm="0 -0.4"/>
          </default>
          <default class="right/thproximal">
            <joint range="0 1.22173"/>
            <general ctrlrange="0 1.22173" forcerange="-2 2"/>
          </default>
          <default class="right/thhub">
            <joint range="-0.20944 0.20944"/>
            <general ctrlrange="-0.20944 0.20944" gainprm="0.5" biasprm="0 -0.5"/>
          </default>
          <default class="right/thmiddle">
            <joint range="-0.698132 0.698132"/>
            <general ctrlrange="-0.698132 0.698132" gainprm="1.5" biasprm="0 -1.5"/>
          </default>
          <default class="right/thdistal">
            <joint range="-0.261799 1.5708"/>
            <general ctrlrange="-0.261799 1.5708"/>
          </default>
        </default>
        <default class="right/metacarpal">
          <joint range="0 0.785398"/>
          <general ctrlrange="0 0.785398"/>
        </default>
        <default class="right/knuckle">
          <joint range="-0.349066 0.349066"/>
          <general ctrlrange="-0.349066 0.349066"/>
        </default>
        <default class="right/proximal">
          <joint range="-0.261799 1.5708"/>
          <general ctrlrange="-0.261799 1.5708"/>
        </default>
        <default class="right/middle_distal">
          <joint range="0 1.5708"/>
          <general ctrlrange="0 3.1415" gainprm="0.5" biasprm="0 -0.5"/>
        </default>
        <default class="right/plastic">
          <geom solref="0.005" solimp="0.5 0.99 0.0001"/>
          <default class="right/plastic_visual">
            <geom type="mesh" contype="0" conaffinity="0" group="2" material="black"/>
          </default>
          <default class="right/plastic_collision">
            <geom group="3"/>
          </default>
        </default>
      </default>
    </default>
  </default>

  <asset>
    <texture type="skybox" colorspace="auto" builtin="gradient" rgb1="0.3 0.5 0.7" rgb2="0 0 0" width="512" height="3072"/>
    <texture type="2d" colorspace="auto" name="groundplane" builtin="checker" mark="edge" rgb1="0.2 0.3 0.4" rgb2="0.1 0.2 0.3" markrgb="0.8 0.8 0.8" width="300" height="300"/>
    <material name="black" shininess="0.25" rgba="0.16355 0.16355 0.16355 1"/>
    <material name="gray" specular="0" shininess="0.25" rgba="0.80848 0.80848 0.80848 1"/>
    <material name="metallic" specular="0" shininess="0.25" rgba="0.9 0.9 0.9 1"/>
    <material name="groundplane" texture="groundplane" texuniform="true" texrepeat="5 5" reflectance="0.2"/>
    <material name="right/black" shininess="0.25" rgba="0.16355 0.16355 0.16355 1"/>
    <material name="right/gray" specular="0" shininess="0.25" rgba="0.80848 0.80848 0.80848 1"/>
    <material name="right/metallic" specular="0" shininess="0.25" rgba="0.9 0.9 0.9 1"/>
    <mesh name="forearm_0" class="left_hand" content_type="model/obj" file="forearm_0.obj"/>
    <mesh name="forearm_1" class="left_hand" content_type="model/obj" file="forearm_1.obj"/>
    <mesh name="forearm_collision" class="left_hand" content_type="model/obj" file="forearm_collision.obj"/>
    <mesh name="wrist" class="left_hand" content_type="model/obj" file="wrist.obj" scale="-0.001 0.001 0.001"/>
    <mesh name="palm" class="left_hand" content_type="model/obj" file="palm.obj" scale="-0.001 0.001 0.001"/>
    <mesh name="f_knuckle" class="left_hand" content_type="model/obj" file="f_knuckle.obj"/>
    <mesh name="f_proximal" class="left_hand" content_type="model/obj" file="f_proximal.obj"/>
    <mesh name="f_middle" class="left_hand" content_type="model/obj" file="f_middle.obj"/>
    <mesh name="f_distal_pst" class="left_hand" content_type="model/obj" file="f_distal_pst.obj"/>
    <mesh name="lf_metacarpal" class="left_hand" content_type="model/obj" file="lf_metacarpal.obj" scale="-0.001 0.001 0.001"/>
    <mesh name="th_proximal" class="left_hand" content_type="model/obj" file="th_proximal.obj"/>
    <mesh name="th_middle" class="left_hand" content_type="model/obj" file="th_middle.obj"/>
    <mesh name="th_distal_pst" class="left_hand" content_type="model/obj" file="th_distal_pst.obj"/>
    <mesh name="right/forearm_0" class="right/right_hand" content_type="model/obj" file="forearm_0.obj"/>
    <mesh name="right/forearm_1" class="right/right_hand" content_type="model/obj" file="forearm_1.obj"/>
    <mesh name="right/forearm_collision" class="right/right_hand" content_type="model/obj" file="forearm_collision.obj"/>
    <mesh name="right/wrist" class="right/right_hand" content_type="model/obj" file="wrist.obj"/>
    <mesh name="right/palm" class="right/right_hand" content_type="model/obj" file="palm.obj"/>
    <mesh name="right/f_knuckle" class="right/right_hand" content_type="model/obj" file="f_knuckle.obj"/>
    <mesh name="right/f_proximal" class="right/right_hand" content_type="model/obj" file="f_proximal.obj"/>
    <mesh name="right/f_middle" class="right/right_hand" file="f_middle.obj"/>
    <mesh name="right/f_distal_pst" class="right/right_hand" content_type="model/obj" file="f_distal_pst.obj"/>
    <mesh name="right/lf_metacarpal" class="right/right_hand" content_type="model/obj" file="lf_metacarpal.obj"/>
    <mesh name="right/th_proximal" class="right/right_hand" file="th_proximal.obj"/>
    <mesh name="right/th_middle" class="right/right_hand" content_type="model/obj" file="th_middle.obj"/>
    <mesh name="right/th_distal_pst" class="right/right_hand" content_type="model/obj" file="th_distal_pst.obj"/>
  </asset>

  <worldbody>
    <geom name="floor" size="0 0 0.05" pos="0 0 -0.1" type="plane" material="groundplane"/>
    <light pos="0 0 1" dir="0 0 -1"/>
    <light pos="0.3 0 1.5" dir="0 0 -1" type="directional"/>
    <body name="lh_forearm" childclass="left_hand" pos="0 -0.12 0" quat="0 0.707107 0 0.707107">
      <inertial pos="0 0 0.09" mass="3" diaginertia="0.0138 0.0138 0.00744"/>
      <geom class="plastic_visual" material="gray" mesh="forearm_0"/>
      <geom class="plastic_visual" mesh="forearm_1"/>
      <geom class="plastic_collision" type="mesh" mesh="forearm_collision"/>
      <geom class="plastic_collision" size="0.035 0.035 0.035" pos="0.01 0 0.181" quat="0.380188 0.924909 0 0" type="box"/>
      <body name="lh_wrist" pos="0.01 0 0.21301" quat="0.707107 0 0 0.707107">
        <inertial pos="0 0 0.029" quat="0.5 0.5 0.5 0.5" mass="0.1" diaginertia="6.4e-05 4.38e-05 3.5e-05"/>
        <joint name="lh_WRJ2" class="wrist_y" pos="0 0 0" axis="0 -1 0"/>
        <geom class="plastic_visual" material="metallic" mesh="wrist"/>
        <geom class="plastic_collision" size="0.0135 0.015" quat="0.499998 0.5 0.5 -0.500002" type="cylinder"/>
        <geom class="plastic_collision" size="0.011 0.005" pos="0.026 0 0.034" quat="0.707107 0 0.707107 0" type="cylinder"/>
        <geom class="plastic_collision" size="0.011 0.005" pos="-0.031 0 0.034" quat="0.707107 0 0.707107 0" type="cylinder"/>
        <geom class="plastic_collision" size="0.0135 0.009 0.005" pos="0.021 0 0.011" quat="-0.923879 0 0.382684 0" type="box"/>
        <geom class="plastic_collision" size="0.0135 0.009 0.005" pos="-0.026 0 0.01" quat="-0.923879 0 -0.382684 0" type="box"/>
        <body name="lh_palm" pos="0 0 0.034">
          <inertial pos="0 0 0.035" quat="0.707107 0 0 0.707107" mass="0.3" diaginertia="0.0005287 0.0003581 0.000191"/>
          <joint name="lh_WRJ1" class="wrist_x" pos="0 0 0" axis="1 0 0"/>
          <geom class="plastic_visual" mesh="palm"/>
          <geom class="plastic_collision" size="0.031 0.0035 0.049" pos="-0.011 0.0085 0.038" type="box"/>
          <geom class="plastic_collision" size="0.018 0.0085 0.049" pos="0.002 -0.0035 0.038" type="box"/>
          <geom class="plastic_collision" size="0.013 0.0085 0.005" pos="-0.029 -0.0035 0.082" type="box"/>
          <geom class="plastic_collision" size="0.013 0.007 0.009" pos="-0.0265 -0.001 0.07" quat="0.987241 0.0990545 0.0124467 -0.124052" type="box"/>
          <geom class="plastic_collision" size="0.0105 0.0135 0.0112" pos="-0.0315 -0.0085 0.001" type="box"/>
          <geom class="plastic_collision" size="0.011 0.0025 0.015" pos="-0.0125 -0.015 0.004" quat="-0.971338 0 0 -0.237703" type="box"/>
          <geom class="plastic_collision" size="0.009 0.012 0.002" pos="-0.011 0 0.089" type="box"/>
          <geom class="plastic_collision" size="0.01 0.012 0.02" pos="0.03 0 0.009" type="box"/>
          <body name="lh_ffknuckle" pos="-0.033 0 0.095">
            <inertial pos="0 0 0" quat="0.5 0.5 -0.5 0.5" mass="0.008" diaginertia="3.2e-07 2.6e-07 2.6e-07"/>
            <joint name="lh_FFJ4" class="knuckle" pos="0 0 0" axis="0 1 0"/>
            <geom class="plastic_visual" pos="0 0 0.0005" material="metallic" mesh="f_knuckle"/>
            <geom class="plastic_collision" size="0.009 0.009" quat="0.707107 0 0.707107 0" type="cylinder"/>
            <body name="lh_ffproximal">
              <inertial pos="0 0 0.0225" quat="0.707107 0 0 0.707107" mass="0.03" diaginertia="1e-05 9.8e-06 1.8e-06"/>
              <joint name="lh_FFJ3" class="proximal" pos="0 0 0" axis="1 0 0"/>
              <geom class="plastic_visual" mesh="f_proximal"/>
              <geom class="plastic_collision" size="0.009 0.02" pos="0 0 0.025" type="capsule"/>
              <body name="lh_ffmiddle" pos="0 0 0.045">
                <inertial pos="0 0 0.0125" quat="0.707107 0 0 0.707107" mass="0.017" diaginertia="2.7e-06 2.6e-06 8.7e-07"/>
                <joint name="lh_FFJ2" class="middle_distal" pos="0 0 0" axis="1 0 0"/>
                <geom class="plastic_visual" mesh="f_middle"/>
                <geom class="plastic_collision" size="0.009 0.0125" pos="0 0 0.0125" type="capsule"/>
                <body name="lh_ffdistal" pos="0 0 0.025">
                  <inertial pos="0 0 0.0130769" quat="0.707107 0 0 0.707107" mass="0.013" diaginertia="1.28092e-06 1.12092e-06 5.3e-07"/>
                  <joint name="lh_FFJ1" class="middle_distal" pos="0 0 0" axis="1 0 0"/>
                  <geom class="plastic_visual" mesh="f_distal_pst"/>
                  <geom class="plastic_collision" type="mesh" mesh="f_distal_pst"/>
                </body>
              </body>
            </body>
          </body>
          <body name="lh_mfknuckle" pos="-0.011 0 0.099">
            <inertial pos="0 0 0" quat="0.5 0.5 -0.5 0.5" mass="0.008" diaginertia="3.2e-07 2.6e-07 2.6e-07"/>
            <joint name="lh_MFJ4" class="knuckle" pos="0 0 0" axis="0 1 0"/>
            <geom class="plastic_visual" pos="0 0 0.0005" material="metallic" mesh="f_knuckle"/>
            <geom class="plastic_collision" size="0.009 0.009" quat="0.707107 0 0.707107 0" type="cylinder"/>
            <body name="lh_mfproximal">
              <inertial pos="0 0 0.0225" quat="0.707107 0 0 0.707107" mass="0.03" diaginertia="1e-05 9.8e-06 1.8e-06"/>
              <joint name="lh_MFJ3" class="proximal" pos="0 0 0" axis="1 0 0"/>
              <geom class="plastic_visual" mesh="f_proximal"/>
              <geom class="plastic_collision" size="0.009 0.02" pos="0 0 0.025" type="capsule"/>
              <body name="lh_mfmiddle" pos="0 0 0.045">
                <inertial pos="0 0 0.0125" quat="0.707107 0 0 0.707107" mass="0.017" diaginertia="2.7e-06 2.6e-06 8.7e-07"/>
                <joint name="lh_MFJ2" class="middle_distal" pos="0 0 0" axis="1 0 0"/>
                <geom class="plastic_visual" mesh="f_middle"/>
                <geom class="plastic_collision" size="0.009 0.0125" pos="0 0 0.0125" type="capsule"/>
                <body name="lh_mfdistal" pos="0 0 0.025">
                  <inertial pos="0 0 0.0130769" quat="0.707107 0 0 0.707107" mass="0.013" diaginertia="1.28092e-06 1.12092e-06 5.3e-07"/>
                  <joint name="lh_MFJ1" class="middle_distal" pos="0 0 0" axis="1 0 0"/>
                  <geom class="plastic_visual" mesh="f_distal_pst"/>
                  <geom class="plastic_collision" type="mesh" mesh="f_distal_pst"/>
                </body>
              </body>
            </body>
          </body>
          <body name="lh_rfknuckle" pos="0.011 0 0.095">
            <inertial pos="0 0 0" quat="0.5 0.5 -0.5 0.5" mass="0.008" diaginertia="3.2e-07 2.6e-07 2.6e-07"/>
            <joint name="lh_RFJ4" class="knuckle" pos="0 0 0" axis="0 -1 0"/>
            <geom class="plastic_visual" pos="0 0 0.0005" material="metallic" mesh="f_knuckle"/>
            <geom class="plastic_collision" size="0.009 0.009" quat="0.707107 0 0.707107 0" type="cylinder"/>
            <body name="lh_rfproximal">
              <inertial pos="0 0 0.0225" quat="0.707107 0 0 0.707107" mass="0.03" diaginertia="1e-05 9.8e-06 1.8e-06"/>
              <joint name="lh_RFJ3" class="proximal" pos="0 0 0" axis="1 0 0"/>
              <geom class="plastic_visual" mesh="f_proximal"/>
              <geom class="plastic_collision" size="0.009 0.02" pos="0 0 0.025" type="capsule"/>
              <body name="lh_rfmiddle" pos="0 0 0.045">
                <inertial pos="0 0 0.0125" quat="0.707107 0 0 0.707107" mass="0.017" diaginertia="2.7e-06 2.6e-06 8.7e-07"/>
                <joint name="lh_RFJ2" class="middle_distal" pos="0 0 0" axis="1 0 0"/>
                <geom class="plastic_visual" mesh="f_middle"/>
                <geom class="plastic_collision" size="0.009 0.0125" pos="0 0 0.0125" type="capsule"/>
                <body name="lh_rfdistal" pos="0 0 0.025">
                  <inertial pos="0 0 0.0130769" quat="0.707107 0 0 0.707107" mass="0.013" diaginertia="1.28092e-06 1.12092e-06 5.3e-07"/>
                  <joint name="lh_RFJ1" class="middle_distal" pos="0 0 0" axis="1 0 0"/>
                  <geom class="plastic_visual" mesh="f_distal_pst"/>
                  <geom class="plastic_collision" type="mesh" mesh="f_distal_pst"/>
                </body>
              </body>
            </body>
          </body>
          <body name="lh_lfmetacarpal" pos="0.033 0 0.02071">
            <inertial pos="0 0 0.04" quat="0.707107 0 0 0.707107" mass="0.03" diaginertia="1.638e-05 1.45e-05 4.272e-06"/>
            <joint name="lh_LFJ5" class="metacarpal" pos="0 0 0" axis="0.573576 0 -0.819152"/>
            <geom class="plastic_visual" mesh="lf_metacarpal"/>
            <geom class="plastic_collision" size="0.011 0.012 0.025" pos="-0.002 0 0.033" type="box"/>
            <body name="lh_lfknuckle" pos="0 0 0.06579">
              <inertial pos="0 0 0" quat="0.5 0.5 -0.5 0.5" mass="0.008" diaginertia="3.2e-07 2.6e-07 2.6e-07"/>
              <joint name="lh_LFJ4" class="knuckle" pos="0 0 0" axis="0 -1 0"/>
              <geom class="plastic_visual" pos="0 0 0.0005" material="metallic" mesh="f_knuckle"/>
              <geom class="plastic_collision" size="0.009 0.009" quat="0.707107 0 0.707107 0" type="cylinder"/>
              <body name="lh_lfproximal">
                <inertial pos="0 0 0.0225" quat="0.707107 0 0 0.707107" mass="0.03" diaginertia="1e-05 9.8e-06 1.8e-06"/>
                <joint name="lh_LFJ3" class="proximal" pos="0 0 0" axis="1 0 0"/>
                <geom class="plastic_visual" mesh="f_proximal"/>
                <geom class="plastic_collision" size="0.009 0.02" pos="0 0 0.025" type="capsule"/>
                <body name="lh_lfmiddle" pos="0 0 0.045">
                  <inertial pos="0 0 0.0125" quat="0.707107 0 0 0.707107" mass="0.017" diaginertia="2.7e-06 2.6e-06 8.7e-07"/>
                  <joint name="lh_LFJ2" class="middle_distal" pos="0 0 0" axis="1 0 0"/>
                  <geom class="plastic_visual" mesh="f_middle"/>
                  <geom class="plastic_collision" size="0.009 0.0125" pos="0 0 0.0125" type="capsule"/>
                  <body name="lh_lfdistal" pos="0 0 0.025">
                    <inertial pos="0 0 0.0130769" quat="0.707107 0 0 0.707107" mass="0.013" diaginertia="1.28092e-06 1.12092e-06 5.3e-07"/>
                    <joint name="lh_LFJ1" class="middle_distal" pos="0 0 0" axis="1 0 0"/>
                    <geom class="plastic_visual" mesh="f_distal_pst"/>
                    <geom class="plastic_collision" type="mesh" mesh="f_distal_pst"/>
                  </body>
                </body>
              </body>
            </body>
          </body>
          <body name="lh_thbase" pos="-0.034 -0.00858 0.029" quat="0 -0.382683 0 0.92388">
            <inertial pos="0 0 0" mass="0.01" diaginertia="1.6e-07 1.6e-07 1.6e-07"/>
            <joint name="lh_THJ5" class="thbase" pos="0 0 0" axis="0 0 1"/>
            <geom class="plastic_collision" size="0.013"/>
            <body name="lh_thproximal">
              <inertial pos="0 0 0.019" mass="0.04" diaginertia="1.36e-05 1.36e-05 3.13e-06"/>
              <joint name="lh_THJ4" class="thproximal" pos="0 0 0" axis="-1 0 0"/>
              <geom class="plastic_visual" mesh="th_proximal"/>
              <geom class="plastic_collision" size="0.0105 0.009" pos="0 0 0.02" type="capsule"/>
              <body name="lh_thhub" pos="0 0 0.038">
                <inertial pos="0 0 0" mass="0.005" diaginertia="1e-06 1e-06 3e-07"/>
                <joint name="lh_THJ3" class="thhub" pos="0 0 0" axis="-1 0 0"/>
                <geom class="plastic_collision" size="0.011"/>
                <body name="lh_thmiddle">
                  <inertial pos="0 0 0.016" mass="0.02" diaginertia="5.1e-06 5.1e-06 1.21e-06"/>
                  <joint name="lh_THJ2" class="thmiddle" pos="0 0 0" axis="0 -1 0"/>
                  <geom class="plastic_visual" mesh="th_middle"/>
                  <geom class="plastic_collision" size="0.009 0.009" pos="0 0 0.012" type="capsule"/>
                  <geom class="plastic_collision" size="0.01" pos="0 0 0.03"/>
                  <body name="lh_thdistal" pos="0 0 0.032" quat="0.707107 0 0 -0.707107">
                    <inertial pos="0 0 0.0145588" quat="0.707107 0 0 0.707107" mass="0.017" diaginertia="2.37794e-06 2.27794e-06 1e-06"/>
                    <joint name="lh_THJ1" class="thdistal" pos="0 0 0" axis="1 0 0"/>
                    <geom class="plastic_visual" mesh="th_distal_pst"/>
                    <geom class="plastic_collision" type="mesh" mesh="th_distal_pst"/>
                  </body>
                </body>
              </body>
            </body>
          </body>
        </body>
      </body>
    </body>
    <body name="object" pos="0.3 0 0.1">
      <joint type="free"/>
      <geom size="0.03 0.04 0.02" type="ellipsoid" condim="6" priority="1" friction="0.5 0.01 0.003" rgba="0.5 0.7 0.5 1"/>
    </body>
    <body name="right/rh_forearm" childclass="right/right_hand" pos="0 0.12 0" quat="0 0.707107 0 0.707107">
      <inertial pos="0 0 0.09" mass="3" diaginertia="0.0138 0.0138 0.00744"/>
      <geom class="right/plastic_visual" material="right/gray" mesh="right/forearm_0"/>
      <geom class="right/plastic_visual" material="right/black" mesh="right/forearm_1"/>
      <geom class="right/plastic_collision" type="mesh" mesh="right/forearm_collision"/>
      <geom class="right/plastic_collision" size="0.035 0.035 0.035" pos="0.01 0 0.181" quat="0.380188 0.924909 0 0" type="box"/>
      <body name="right/rh_wrist" pos="0.01 0 0.21301" quat="0.707107 0 0 0.707107">
        <inertial pos="0 0 0.029" quat="0.5 0.5 0.5 0.5" mass="0.1" diaginertia="6.4e-05 4.38e-05 3.5e-05"/>
        <joint name="right/rh_WRJ2" class="right/wrist_y" pos="0 0 0" axis="0 1 0"/>
        <geom class="right/plastic_visual" material="right/metallic" mesh="right/wrist"/>
        <geom class="right/plastic_collision" size="0.0135 0.015" quat="0.499998 0.5 0.5 -0.500002" type="cylinder"/>
        <geom class="right/plastic_collision" size="0.011 0.005" pos="-0.026 0 0.034" quat="0.707107 0 0.707107 0" type="cylinder"/>
        <geom class="right/plastic_collision" size="0.011 0.005" pos="0.031 0 0.034" quat="0.707107 0 0.707107 0" type="cylinder"/>
        <geom class="right/plastic_collision" size="0.0135 0.009 0.005" pos="-0.021 0 0.011" quat="0.923879 0 0.382684 0" type="box"/>
        <geom class="right/plastic_collision" size="0.0135 0.009 0.005" pos="0.026 0 0.01" quat="0.923879 0 -0.382684 0" type="box"/>
        <body name="right/rh_palm" pos="0 0 0.034">
          <inertial pos="0 0 0.035" quat="0.707107 0 0 0.707107" mass="0.3" diaginertia="0.0005287 0.0003581 0.000191"/>
          <joint name="right/rh_WRJ1" class="right/wrist_x" pos="0 0 0" axis="1 0 0"/>
          <geom class="right/plastic_visual" material="right/black" mesh="right/palm"/>
          <geom class="right/plastic_collision" size="0.031 0.0035 0.049" pos="0.011 0.0085 0.038" type="box"/>
          <geom class="right/plastic_collision" size="0.018 0.0085 0.049" pos="-0.002 -0.0035 0.038" type="box"/>
          <geom class="right/plastic_collision" size="0.013 0.0085 0.005" pos="0.029 -0.0035 0.082" type="box"/>
          <geom class="right/plastic_collision" size="0.013 0.007 0.009" pos="0.0265 -0.001 0.07" quat="0.987241 0.0990545 0.0124467 0.124052" type="box"/>
          <geom class="right/plastic_collision" size="0.0105 0.0135 0.012" pos="0.0315 -0.0085 0.001" type="box"/>
          <geom class="right/plastic_collision" size="0.011 0.0025 0.015" pos="0.0125 -0.015 0.004" quat="0.971338 0 0 -0.237703" type="box"/>
          <geom class="right/plastic_collision" size="0.009 0.012 0.002" pos="0.011 0 0.089" type="box"/>
          <geom class="right/plastic_collision" size="0.01 0.012 0.02" pos="-0.03 0 0.009" type="box"/>
          <site name="right/grasp_site" pos="0 -0.035 0.09" group="4"/>
          <body name="right/rh_ffknuckle" pos="0.033 0 0.095">
            <inertial pos="0 0 0" quat="0.5 0.5 -0.5 0.5" mass="0.008" diaginertia="3.2e-07 2.6e-07 2.6e-07"/>
            <joint name="right/rh_FFJ4" class="right/knuckle" pos="0 0 0" axis="0 -1 0"/>
            <geom class="right/plastic_visual" pos="0 0 0.0005" material="right/metallic" mesh="right/f_knuckle"/>
            <geom class="right/plastic_collision" size="0.009 0.009" quat="0.707107 0 0.707107 0" type="cylinder"/>
            <body name="right/rh_ffproximal">
              <inertial pos="0 0 0.0225" quat="0.707107 0 0 0.707107" mass="0.03" diaginertia="1e-05 9.8e-06 1.8e-06"/>
              <joint name="right/rh_FFJ3" class="right/proximal" pos="0 0 0" axis="1 0 0"/>
              <geom class="right/plastic_visual" material="right/black" mesh="right/f_proximal"/>
              <geom class="right/plastic_collision" size="0.009 0.02" pos="0 0 0.025" type="capsule"/>
              <body name="right/rh_ffmiddle" pos="0 0 0.045">
                <inertial pos="0 0 0.0125" quat="0.707107 0 0 0.707107" mass="0.017" diaginertia="2.7e-06 2.6e-06 8.7e-07"/>
                <joint name="right/rh_FFJ2" class="right/middle_distal" pos="0 0 0" axis="1 0 0"/>
                <geom class="right/plastic_visual" material="right/black" mesh="right/f_middle"/>
                <geom class="right/plastic_collision" size="0.009 0.0125" pos="0 0 0.0125" type="capsule"/>
                <body name="right/rh_ffdistal" pos="0 0 0.025">
                  <inertial pos="0 0 0.0130769" quat="0.707107 0 0 0.707107" mass="0.013" diaginertia="1.28092e-06 1.12092e-06 5.3e-07"/>
                  <joint name="right/rh_FFJ1" class="right/middle_distal" pos="0 0 0" axis="1 0 0"/>
                  <geom class="right/plastic_visual" material="right/black" mesh="right/f_distal_pst"/>
                  <geom class="right/plastic_collision" type="mesh" mesh="right/f_distal_pst"/>
                </body>
              </body>
            </body>
          </body>
          <body name="right/rh_mfknuckle" pos="0.011 0 0.099">
            <inertial pos="0 0 0" quat="0.5 0.5 -0.5 0.5" mass="0.008" diaginertia="3.2e-07 2.6e-07 2.6e-07"/>
            <joint name="right/rh_MFJ4" class="right/knuckle" pos="0 0 0" axis="0 -1 0"/>
            <geom class="right/plastic_visual" pos="0 0 0.0005" material="right/metallic" mesh="right/f_knuckle"/>
            <geom class="right/plastic_collision" size="0.009 0.009" quat="0.707107 0 0.707107 0" type="cylinder"/>
            <body name="right/rh_mfproximal">
              <inertial pos="0 0 0.0225" quat="0.707107 0 0 0.707107" mass="0.03" diaginertia="1e-05 9.8e-06 1.8e-06"/>
              <joint name="right/rh_MFJ3" class="right/proximal" pos="0 0 0" axis="1 0 0"/>
              <geom class="right/plastic_visual" material="right/black" mesh="right/f_proximal"/>
              <geom class="right/plastic_collision" size="0.009 0.02" pos="0 0 0.025" type="capsule"/>
              <body name="right/rh_mfmiddle" pos="0 0 0.045">
                <inertial pos="0 0 0.0125" quat="0.707107 0 0 0.707107" mass="0.017" diaginertia="2.7e-06 2.6e-06 8.7e-07"/>
                <joint name="right/rh_MFJ2" class="right/middle_distal" pos="0 0 0" axis="1 0 0"/>
                <geom class="right/plastic_visual" material="right/black" mesh="right/f_middle"/>
                <geom class="right/plastic_collision" size="0.009 0.0125" pos="0 0 0.0125" type="capsule"/>
                <body name="right/rh_mfdistal" pos="0 0 0.025">
                  <inertial pos="0 0 0.0130769" quat="0.707107 0 0 0.707107" mass="0.013" diaginertia="1.28092e-06 1.12092e-06 5.3e-07"/>
                  <joint name="right/rh_MFJ1" class="right/middle_distal" pos="0 0 0" axis="1 0 0"/>
                  <geom class="right/plastic_visual" material="right/black" mesh="right/f_distal_pst"/>
                  <geom class="right/plastic_collision" type="mesh" mesh="right/f_distal_pst"/>
                </body>
              </body>
            </body>
          </body>
          <body name="right/rh_rfknuckle" pos="-0.011 0 0.095">
            <inertial pos="0 0 0" quat="0.5 0.5 -0.5 0.5" mass="0.008" diaginertia="3.2e-07 2.6e-07 2.6e-07"/>
            <joint name="right/rh_RFJ4" class="right/knuckle" pos="0 0 0" axis="0 1 0"/>
            <geom class="right/plastic_visual" pos="0 0 0.0005" material="right/metallic" mesh="right/f_knuckle"/>
            <geom class="right/plastic_collision" size="0.009 0.009" quat="0.707107 0 0.707107 0" type="cylinder"/>
            <body name="right/rh_rfproximal">
              <inertial pos="0 0 0.0225" quat="0.707107 0 0 0.707107" mass="0.03" diaginertia="1e-05 9.8e-06 1.8e-06"/>
              <joint name="right/rh_RFJ3" class="right/proximal" pos="0 0 0" axis="1 0 0"/>
              <geom class="right/plastic_visual" material="right/black" mesh="right/f_proximal"/>
              <geom class="right/plastic_collision" size="0.009 0.02" pos="0 0 0.025" type="capsule"/>
              <body name="right/rh_rfmiddle" pos="0 0 0.045">
                <inertial pos="0 0 0.0125" quat="0.707107 0 0 0.707107" mass="0.017" diaginertia="2.7e-06 2.6e-06 8.7e-07"/>
                <joint name="right/rh_RFJ2" class="right/middle_distal" pos="0 0 0" axis="1 0 0"/>
                <geom class="right/plastic_visual" material="right/black" mesh="right/f_middle"/>
                <geom class="right/plastic_collision" size="0.009 0.0125" pos="0 0 0.0125" type="capsule"/>
                <body name="right/rh_rfdistal" pos="0 0 0.025">
                  <inertial pos="0 0 0.0130769" quat="0.707107 0 0 0.707107" mass="0.013" diaginertia="1.28092e-06 1.12092e-06 5.3e-07"/>
                  <joint name="right/rh_RFJ1" class="right/middle_distal" pos="0 0 0" axis="1 0 0"/>
                  <geom class="right/plastic_visual" material="right/black" mesh="right/f_distal_pst"/>
                  <geom class="right/plastic_collision" type="mesh" mesh="right/f_distal_pst"/>
                </body>
              </body>
            </body>
          </body>
          <body name="right/rh_lfmetacarpal" pos="-0.033 0 0.02071">
            <inertial pos="0 0 0.04" quat="0.707107 0 0 0.707107" mass="0.03" diaginertia="1.638e-05 1.45e-05 4.272e-06"/>
            <joint name="right/rh_LFJ5" class="right/metacarpal" pos="0 0 0" axis="0.573576 0 0.819152"/>
            <geom class="right/plastic_visual" material="right/black" mesh="right/lf_metacarpal"/>
            <geom class="right/plastic_collision" size="0.011 0.012 0.025" pos="0.002 0 0.033" type="box"/>
            <body name="right/rh_lfknuckle" pos="0 0 0.06579">
              <inertial pos="0 0 0" quat="0.5 0.5 -0.5 0.5" mass="0.008" diaginertia="3.2e-07 2.6e-07 2.6e-07"/>
              <joint name="right/rh_LFJ4" class="right/knuckle" pos="0 0 0" axis="0 1 0"/>
              <geom class="right/plastic_visual" pos="0 0 0.0005" material="right/metallic" mesh="right/f_knuckle"/>
              <geom class="right/plastic_collision" size="0.009 0.009" quat="0.707107 0 0.707107 0" type="cylinder"/>
              <body name="right/rh_lfproximal">
                <inertial pos="0 0 0.0225" quat="0.707107 0 0 0.707107" mass="0.03" diaginertia="1e-05 9.8e-06 1.8e-06"/>
                <joint name="right/rh_LFJ3" class="right/proximal" pos="0 0 0" axis="1 0 0"/>
                <geom class="right/plastic_visual" material="right/black" mesh="right/f_proximal"/>
                <geom class="right/plastic_collision" size="0.009 0.02" pos="0 0 0.025" type="capsule"/>
                <body name="right/rh_lfmiddle" pos="0 0 0.045">
                  <inertial pos="0 0 0.0125" quat="0.707107 0 0 0.707107" mass="0.017" diaginertia="2.7e-06 2.6e-06 8.7e-07"/>
                  <joint name="right/rh_LFJ2" class="right/middle_distal" pos="0 0 0" axis="1 0 0"/>
                  <geom class="right/plastic_visual" material="right/black" mesh="right/f_middle"/>
                  <geom class="right/plastic_collision" size="0.009 0.0125" pos="0 0 0.0125" type="capsule"/>
                  <body name="right/rh_lfdistal" pos="0 0 0.025">
                    <inertial pos="0 0 0.0130769" quat="0.707107 0 0 0.707107" mass="0.013" diaginertia="1.28092e-06 1.12092e-06 5.3e-07"/>
                    <joint name="right/rh_LFJ1" class="right/middle_distal" pos="0 0 0" axis="1 0 0"/>
                    <geom class="right/plastic_visual" material="right/black" mesh="right/f_distal_pst"/>
                    <geom class="right/plastic_collision" type="mesh" mesh="right/f_distal_pst"/>
                  </body>
                </body>
              </body>
            </body>
          </body>
          <body name="right/rh_thbase" pos="0.034 -0.00858 0.029" quat="0.92388 0 0.382683 0">
            <inertial pos="0 0 0" mass="0.01" diaginertia="1.6e-07 1.6e-07 1.6e-07"/>
            <joint name="right/rh_THJ5" class="right/thbase" pos="0 0 0" axis="0 0 -1"/>
            <geom class="right/plastic_collision" size="0.013"/>
            <body name="right/rh_thproximal">
              <inertial pos="0 0 0.019" mass="0.04" diaginertia="1.36e-05 1.36e-05 3.13e-06"/>
              <joint name="right/rh_THJ4" class="right/thproximal" pos="0 0 0" axis="1 0 0"/>
              <geom class="right/plastic_visual" material="right/black" mesh="right/th_proximal"/>
              <geom class="right/plastic_collision" size="0.0105 0.009" pos="0 0 0.02" type="capsule"/>
              <body name="right/rh_thhub" pos="0 0 0.038">
                <inertial pos="0 0 0" mass="0.005" diaginertia="1e-06 1e-06 3e-07"/>
                <joint name="right/rh_THJ3" class="right/thhub" pos="0 0 0" axis="1 0 0"/>
                <geom class="right/plastic_collision" size="0.011"/>
                <body name="right/rh_thmiddle">
                  <inertial pos="0 0 0.016" mass="0.02" diaginertia="5.1e-06 5.1e-06 1.21e-06"/>
                  <joint name="right/rh_THJ2" class="right/thmiddle" pos="0 0 0" axis="0 -1 0"/>
                  <geom class="right/plastic_visual" material="right/black" mesh="right/th_middle"/>
                  <geom class="right/plastic_collision" size="0.009 0.009" pos="0 0 0.012" type="capsule"/>
                  <geom class="right/plastic_collision" size="0.01" pos="0 0 0.03"/>
                  <body name="right/rh_thdistal" pos="0 0 0.032" quat="0.707107 0 0 -0.707107">
                    <inertial pos="0 0 0.0145588" quat="0.707107 0 0 0.707107" mass="0.017" diaginertia="2.37794e-06 2.27794e-06 1e-06"/>
                    <joint name="right/rh_THJ1" class="right/thdistal" pos="0 0 0" axis="1 0 0"/>
                    <geom class="right/plastic_visual" material="right/black" mesh="right/th_distal_pst"/>
                    <geom class="right/plastic_collision" type="mesh" mesh="right/th_distal_pst"/>
                  </body>
                </body>
              </body>
            </body>
          </body>
        </body>
      </body>
    </body>
  </worldbody>

  <contact>
    <exclude body1="lh_forearm" body2="lh_wrist"/>
    <exclude body1="lh_thproximal" body2="lh_thmiddle"/>
    <exclude body1="right/rh_forearm" body2="right/rh_wrist"/>
    <exclude body1="right/rh_thproximal" body2="right/rh_thmiddle"/>
  </contact>

  <tendon>
    <fixed name="lh_FFJ0">
      <joint joint="lh_FFJ2" coef="1"/>
      <joint joint="lh_FFJ1" coef="1"/>
    </fixed>
    <fixed name="lh_MFJ0">
      <joint joint="lh_MFJ2" coef="1"/>
      <joint joint="lh_MFJ1" coef="1"/>
    </fixed>
    <fixed name="lh_RFJ0">
      <joint joint="lh_RFJ2" coef="1"/>
      <joint joint="lh_RFJ1" coef="1"/>
    </fixed>
    <fixed name="lh_LFJ0">
      <joint joint="lh_LFJ2" coef="1"/>
      <joint joint="lh_LFJ1" coef="1"/>
    </fixed>
    <fixed name="right/rh_FFJ0">
      <joint joint="right/rh_FFJ2" coef="1"/>
      <joint joint="right/rh_FFJ1" coef="1"/>
    </fixed>
    <fixed name="right/rh_MFJ0">
      <joint joint="right/rh_MFJ2" coef="1"/>
      <joint joint="right/rh_MFJ1" coef="1"/>
    </fixed>
    <fixed name="right/rh_RFJ0">
      <joint joint="right/rh_RFJ2" coef="1"/>
      <joint joint="right/rh_RFJ1" coef="1"/>
    </fixed>
    <fixed name="right/rh_LFJ0">
      <joint joint="right/rh_LFJ2" coef="1"/>
      <joint joint="right/rh_LFJ1" coef="1"/>
    </fixed>
  </tendon>

  <actuator>
    <general name="lh_A_WRJ2" class="wrist_y" joint="lh_WRJ2"/>
    <general name="lh_A_WRJ1" class="wrist_x" joint="lh_WRJ1"/>
    <general name="lh_A_THJ5" class="thbase" joint="lh_THJ5"/>
    <general name="lh_A_THJ4" class="thproximal" joint="lh_THJ4"/>
    <general name="lh_A_THJ3" class="thhub" joint="lh_THJ3"/>
    <general name="lh_A_THJ2" class="thmiddle" joint="lh_THJ2"/>
    <general name="lh_A_THJ1" class="thdistal" joint="lh_THJ1"/>
    <general name="lh_A_FFJ4" class="knuckle" joint="lh_FFJ4"/>
    <general name="lh_A_FFJ3" class="proximal" joint="lh_FFJ3"/>
    <general name="lh_A_FFJ0" class="middle_distal" tendon="lh_FFJ0"/>
    <general name="lh_A_MFJ4" class="knuckle" joint="lh_MFJ4"/>
    <general name="lh_A_MFJ3" class="proximal" joint="lh_MFJ3"/>
    <general name="lh_A_MFJ0" class="middle_distal" tendon="lh_MFJ0"/>
    <general name="lh_A_RFJ4" class="knuckle" joint="lh_RFJ4"/>
    <general name="lh_A_RFJ3" class="proximal" joint="lh_RFJ3"/>
    <general name="lh_A_RFJ0" class="middle_distal" tendon="lh_RFJ0"/>
    <general name="lh_A_LFJ5" class="metacarpal" joint="lh_LFJ5"/>
    <general name="lh_A_LFJ4" class="knuckle" joint="lh_LFJ4"/>
    <general name="lh_A_LFJ3" class="proximal" joint="lh_LFJ3"/>
    <general name="lh_A_LFJ0" class="middle_distal" tendon="lh_LFJ0"/>
    <general name="right/rh_A_WRJ2" class="right/wrist_y" joint="right/rh_WRJ2"/>
    <general name="right/rh_A_WRJ1" class="right/wrist_x" joint="right/rh_WRJ1"/>
    <general name="right/rh_A_THJ5" class="right/thbase" joint="right/rh_THJ5"/>
    <general name="right/rh_A_THJ4" class="right/thproximal" joint="right/rh_THJ4"/>
    <general name="right/rh_A_THJ3" class="right/thhub" joint="right/rh_THJ3"/>
    <general name="right/rh_A_THJ2" class="right/thmiddle" joint="right/rh_THJ2"/>
    <general name="right/rh_A_THJ1" class="right/thdistal" joint="right/rh_THJ1"/>
    <general name="right/rh_A_FFJ4" class="right/knuckle" joint="right/rh_FFJ4"/>
    <general name="right/rh_A_FFJ3" class="right/proximal" joint="right/rh_FFJ3"/>
    <general name="right/rh_A_FFJ0" class="right/middle_distal" tendon="right/rh_FFJ0"/>
    <general name="right/rh_A_MFJ4" class="right/knuckle" joint="right/rh_MFJ4"/>
    <general name="right/rh_A_MFJ3" class="right/proximal" joint="right/rh_MFJ3"/>
    <general name="right/rh_A_MFJ0" class="right/middle_distal" tendon="right/rh_MFJ0"/>
    <general name="right/rh_A_RFJ4" class="right/knuckle" joint="right/rh_RFJ4"/>
    <general name="right/rh_A_RFJ3" class="right/proximal" joint="right/rh_RFJ3"/>
    <general name="right/rh_A_RFJ0" class="right/middle_distal" tendon="right/rh_RFJ0"/>
    <general name="right/rh_A_LFJ5" class="right/metacarpal" joint="right/rh_LFJ5"/>
    <general name="right/rh_A_LFJ4" class="right/knuckle" joint="right/rh_LFJ4"/>
    <general name="right/rh_A_LFJ3" class="right/proximal" joint="right/rh_LFJ3"/>
    <general name="right/rh_A_LFJ0" class="right/middle_distal" tendon="right/rh_LFJ0"/>
  </actuator>
</mujoco>
